[2024-11-14T01:01:56.826+0000] {local_task_job_runner.py:120} INFO - ::group::Pre task execution logs
[2024-11-14T01:01:56.843+0000] {taskinstance.py:2076} INFO - Dependencies all met for dep_context=non-requeueable deps ti=<TaskInstance: PopulationDataToSnowflake.load_population_data manual__2024-11-14T01:01:48.815615+00:00 [queued]>
[2024-11-14T01:01:56.849+0000] {taskinstance.py:2076} INFO - Dependencies all met for dep_context=requeueable deps ti=<TaskInstance: PopulationDataToSnowflake.load_population_data manual__2024-11-14T01:01:48.815615+00:00 [queued]>
[2024-11-14T01:01:56.852+0000] {taskinstance.py:2306} INFO - Starting attempt 1 of 1
[2024-11-14T01:01:56.861+0000] {taskinstance.py:2330} INFO - Executing <Task(_PythonDecoratedOperator): load_population_data> on 2024-11-14 01:01:48.815615+00:00
[2024-11-14T01:01:56.886+0000] {warnings.py:110} WARNING - /home/***/.local/lib/python3.12/site-packages/***/task/task_runner/standard_task_runner.py:61: DeprecationWarning: This process (pid=1250) is multi-threaded, use of fork() may lead to deadlocks in the child.
  pid = os.fork()

[2024-11-14T01:01:56.889+0000] {standard_task_runner.py:90} INFO - Running: ['***', 'tasks', 'run', 'PopulationDataToSnowflake', 'load_population_data', 'manual__2024-11-14T01:01:48.815615+00:00', '--job-id', '65', '--raw', '--subdir', 'DAGS_FOLDER/PopulationDataToSnowflake.py', '--cfg-path', '/tmp/tmpq6z__a48']
[2024-11-14T01:01:56.891+0000] {standard_task_runner.py:63} INFO - Started process 1252 to run task
[2024-11-14T01:01:56.892+0000] {standard_task_runner.py:91} INFO - Job 65: Subtask load_population_data
[2024-11-14T01:01:56.964+0000] {task_command.py:426} INFO - Running <TaskInstance: PopulationDataToSnowflake.load_population_data manual__2024-11-14T01:01:48.815615+00:00 [running]> on host 3627cdc70e56
[2024-11-14T01:01:57.039+0000] {taskinstance.py:2648} INFO - Exporting env vars: AIRFLOW_CTX_DAG_OWNER='***' AIRFLOW_CTX_DAG_ID='PopulationDataToSnowflake' AIRFLOW_CTX_TASK_ID='load_population_data' AIRFLOW_CTX_EXECUTION_DATE='2024-11-14T01:01:48.815615+00:00' AIRFLOW_CTX_TRY_NUMBER='1' AIRFLOW_CTX_DAG_RUN_ID='manual__2024-11-14T01:01:48.815615+00:00'
[2024-11-14T01:01:57.043+0000] {taskinstance.py:430} INFO - ::endgroup::
[2024-11-14T01:01:57.053+0000] {base.py:84} INFO - Using connection ID 'snowflake_conn' for task execution.
[2024-11-14T01:01:57.055+0000] {connection.py:399} INFO - Snowflake Connector for Python Version: 3.10.0, Python Version: 3.12.3, Platform: Linux-5.10.25-linuxkit-aarch64-with-glibc2.36
[2024-11-14T01:01:57.057+0000] {connection.py:1239} INFO - This connection is in OCSP Fail Open Mode. TLS Certificates would be checked for validity and revocation status. Any other Certificate Revocation related exceptions or OCSP Responder failures would be disregarded in favor of connectivity.
[2024-11-14T01:01:58.370+0000] {cursor.py:1149} INFO - Number of results in first chunk: 1
[2024-11-14T01:01:58.618+0000] {cursor.py:1149} INFO - Number of results in first chunk: 1
[2024-11-14T02:07:23.849+0000] {local_task_job_runner.py:310} WARNING - State of this instance has been externally set to None. Terminating instance.
[2024-11-14T02:07:23.885+0000] {local_task_job_runner.py:222} INFO - ::endgroup::
[2024-11-14T02:07:23.901+0000] {process_utils.py:132} INFO - Sending 15 to group 1252. PIDs of all processes in the group: [1252]
[2024-11-14T02:07:23.905+0000] {process_utils.py:87} INFO - Sending the signal 15 to group 1252
[2024-11-14T02:07:23.911+0000] {taskinstance.py:2611} ERROR - Received SIGTERM. Terminating subprocesses.
[2024-11-14T02:07:23.942+0000] {taskinstance.py:441} INFO - ::group::Post task execution logs
[2024-11-14T02:07:24.030+0000] {taskinstance.py:2905} ERROR - Task failed with exception
Traceback (most recent call last):
  File "/home/airflow/.local/lib/python3.12/site-packages/airflow/models/taskinstance.py", line 465, in _execute_task
    result = _execute_callable(context=context, **execute_callable_kwargs)
             ^^^^^^^^^^^^^^^^^^^^^^^^^^^^^^^^^^^^^^^^^^^^^^^^^^^^^^^^^^^^^
  File "/home/airflow/.local/lib/python3.12/site-packages/airflow/models/taskinstance.py", line 432, in _execute_callable
    return execute_callable(context=context, **execute_callable_kwargs)
           ^^^^^^^^^^^^^^^^^^^^^^^^^^^^^^^^^^^^^^^^^^^^^^^^^^^^^^^^^^^^
  File "/home/airflow/.local/lib/python3.12/site-packages/airflow/models/baseoperator.py", line 400, in wrapper
    return func(self, *args, **kwargs)
           ^^^^^^^^^^^^^^^^^^^^^^^^^^^
  File "/home/airflow/.local/lib/python3.12/site-packages/airflow/decorators/base.py", line 265, in execute
    return_value = super().execute(context)
                   ^^^^^^^^^^^^^^^^^^^^^^^^
  File "/home/airflow/.local/lib/python3.12/site-packages/airflow/models/baseoperator.py", line 400, in wrapper
    return func(self, *args, **kwargs)
           ^^^^^^^^^^^^^^^^^^^^^^^^^^^
  File "/home/airflow/.local/lib/python3.12/site-packages/airflow/operators/python.py", line 235, in execute
    return_value = self.execute_callable()
                   ^^^^^^^^^^^^^^^^^^^^^^^
  File "/home/airflow/.local/lib/python3.12/site-packages/airflow/operators/python.py", line 252, in execute_callable
    return self.python_callable(*self.op_args, **self.op_kwargs)
           ^^^^^^^^^^^^^^^^^^^^^^^^^^^^^^^^^^^^^^^^^^^^^^^^^^^^^
  File "/opt/airflow/dags/PopulationDataToSnowflake.py", line 102, in load_population_data
    cur.execute(sql, (record['country'], record['year'], record['population']))
  File "/home/airflow/.local/lib/python3.12/site-packages/snowflake/connector/cursor.py", line 977, in execute
    ret = self._execute_helper(query, **kwargs)
          ^^^^^^^^^^^^^^^^^^^^^^^^^^^^^^^^^^^^^
  File "/home/airflow/.local/lib/python3.12/site-packages/snowflake/connector/cursor.py", line 694, in _execute_helper
    ret = self._connection.cmd_query(
          ^^^^^^^^^^^^^^^^^^^^^^^^^^^
  File "/home/airflow/.local/lib/python3.12/site-packages/snowflake/connector/connection.py", line 1309, in cmd_query
    ret = self.rest.request(
          ^^^^^^^^^^^^^^^^^^
  File "/home/airflow/.local/lib/python3.12/site-packages/snowflake/connector/network.py", line 493, in request
    return self._post_request(
           ^^^^^^^^^^^^^^^^^^^
  File "/home/airflow/.local/lib/python3.12/site-packages/snowflake/connector/network.py", line 734, in _post_request
    ret = self.fetch(
          ^^^^^^^^^^^
  File "/home/airflow/.local/lib/python3.12/site-packages/snowflake/connector/network.py", line 843, in fetch
    ret = self._request_exec_wrapper(
          ^^^^^^^^^^^^^^^^^^^^^^^^^^^
  File "/home/airflow/.local/lib/python3.12/site-packages/snowflake/connector/network.py", line 884, in _request_exec_wrapper
    return_object = self._request_exec(
                    ^^^^^^^^^^^^^^^^^^^
  File "/home/airflow/.local/lib/python3.12/site-packages/snowflake/connector/network.py", line 1078, in _request_exec
    raw_ret = session.request(
              ^^^^^^^^^^^^^^^^
  File "/home/airflow/.local/lib/python3.12/site-packages/snowflake/connector/vendored/requests/sessions.py", line 589, in request
    resp = self.send(prep, **send_kwargs)
           ^^^^^^^^^^^^^^^^^^^^^^^^^^^^^^
  File "/home/airflow/.local/lib/python3.12/site-packages/snowflake/connector/vendored/requests/sessions.py", line 703, in send
    r = adapter.send(request, **kwargs)
        ^^^^^^^^^^^^^^^^^^^^^^^^^^^^^^^
  File "/home/airflow/.local/lib/python3.12/site-packages/snowflake/connector/vendored/requests/adapters.py", line 486, in send
    resp = conn.urlopen(
           ^^^^^^^^^^^^^
  File "/home/airflow/.local/lib/python3.12/site-packages/snowflake/connector/vendored/urllib3/connectionpool.py", line 715, in urlopen
    httplib_response = self._make_request(
                       ^^^^^^^^^^^^^^^^^^^
  File "/home/airflow/.local/lib/python3.12/site-packages/snowflake/connector/vendored/urllib3/connectionpool.py", line 467, in _make_request
    six.raise_from(e, None)
  File "<string>", line 3, in raise_from
  File "/home/airflow/.local/lib/python3.12/site-packages/snowflake/connector/vendored/urllib3/connectionpool.py", line 462, in _make_request
    httplib_response = conn.getresponse()
                       ^^^^^^^^^^^^^^^^^^
  File "/usr/local/lib/python3.12/http/client.py", line 1428, in getresponse
    response.begin()
  File "/usr/local/lib/python3.12/http/client.py", line 331, in begin
    version, status, reason = self._read_status()
                              ^^^^^^^^^^^^^^^^^^^
  File "/usr/local/lib/python3.12/http/client.py", line 292, in _read_status
    line = str(self.fp.readline(_MAXLINE + 1), "iso-8859-1")
               ^^^^^^^^^^^^^^^^^^^^^^^^^^^^^^
  File "/usr/local/lib/python3.12/socket.py", line 707, in readinto
    return self._sock.recv_into(b)
           ^^^^^^^^^^^^^^^^^^^^^^^
  File "/home/airflow/.local/lib/python3.12/site-packages/snowflake/connector/vendored/urllib3/contrib/pyopenssl.py", line 330, in recv_into
    if not util.wait_for_read(self.socket, self.socket.gettimeout()):
           ^^^^^^^^^^^^^^^^^^^^^^^^^^^^^^^^^^^^^^^^^^^^^^^^^^^^^^^^^
  File "/home/airflow/.local/lib/python3.12/site-packages/snowflake/connector/vendored/urllib3/util/wait.py", line 145, in wait_for_read
    return wait_for_socket(sock, read=True, timeout=timeout)
           ^^^^^^^^^^^^^^^^^^^^^^^^^^^^^^^^^^^^^^^^^^^^^^^^^
  File "/home/airflow/.local/lib/python3.12/site-packages/snowflake/connector/vendored/urllib3/util/wait.py", line 106, in poll_wait_for_socket
    return bool(_retry_on_intr(do_poll, timeout))
                ^^^^^^^^^^^^^^^^^^^^^^^^^^^^^^^^
  File "/home/airflow/.local/lib/python3.12/site-packages/snowflake/connector/vendored/urllib3/util/wait.py", line 43, in _retry_on_intr
    return fn(timeout)
           ^^^^^^^^^^^
  File "/home/airflow/.local/lib/python3.12/site-packages/snowflake/connector/vendored/urllib3/util/wait.py", line 104, in do_poll
    return poll_obj.poll(t)
           ^^^^^^^^^^^^^^^^
  File "/home/airflow/.local/lib/python3.12/site-packages/airflow/models/taskinstance.py", line 2613, in signal_handler
    raise AirflowTaskTerminated("Task received SIGTERM signal")
airflow.exceptions.AirflowTaskTerminated: Task received SIGTERM signal
[2024-11-14T02:07:24.109+0000] {taskinstance.py:1206} INFO - Marking task as FAILED. dag_id=PopulationDataToSnowflake, task_id=load_population_data, run_id=manual__2024-11-14T01:01:48.815615+00:00, execution_date=20241114T010148, start_date=20241114T010156, end_date=20241114T020724
[2024-11-14T02:07:24.252+0000] {standard_task_runner.py:110} ERROR - Failed to execute job 65 for task load_population_data ((psycopg2.errors.ForeignKeyViolation) insert or update on table "task_fail" violates foreign key constraint "task_fail_ti_fkey"
DETAIL:  Key (dag_id, task_id, run_id, map_index)=(PopulationDataToSnowflake, load_population_data, manual__2024-11-14T01:01:48.815615+00:00, -1) is not present in table "task_instance".

[SQL: INSERT INTO task_fail (task_id, dag_id, run_id, map_index, start_date, end_date, duration) VALUES (%(task_id)s, %(dag_id)s, %(run_id)s, %(map_index)s, %(start_date)s, %(end_date)s, %(duration)s) RETURNING task_fail.id]
[parameters: {'task_id': 'load_population_data', 'dag_id': 'PopulationDataToSnowflake', 'run_id': 'manual__2024-11-14T01:01:48.815615+00:00', 'map_index': -1, 'start_date': datetime.datetime(2024, 11, 14, 1, 1, 56, 844812, tzinfo=Timezone('UTC')), 'end_date': datetime.datetime(2024, 11, 14, 2, 7, 24, 84969, tzinfo=Timezone('UTC')), 'duration': 3927}]
(Background on this error at: https://sqlalche.me/e/14/gkpj); 1252)
[2024-11-14T02:07:24.732+0000] {process_utils.py:80} INFO - Process psutil.Process(pid=1252, status='terminated', exitcode=1, started='01:01:55') (1252) terminated with exit code 1
