[2024-11-14T04:19:20.925+0000] {local_task_job_runner.py:120} INFO - ::group::Pre task execution logs
[2024-11-14T04:19:21.009+0000] {taskinstance.py:2076} INFO - Dependencies all met for dep_context=non-requeueable deps ti=<TaskInstance: BuildELT_dbt.dbt_run manual__2024-11-14T04:19:18.165294+00:00 [queued]>
[2024-11-14T04:19:21.042+0000] {taskinstance.py:2076} INFO - Dependencies all met for dep_context=requeueable deps ti=<TaskInstance: BuildELT_dbt.dbt_run manual__2024-11-14T04:19:18.165294+00:00 [queued]>
[2024-11-14T04:19:21.045+0000] {taskinstance.py:2306} INFO - Starting attempt 1 of 1
[2024-11-14T04:19:21.214+0000] {taskinstance.py:2330} INFO - Executing <Task(BashOperator): dbt_run> on 2024-11-14 04:19:18.165294+00:00
[2024-11-14T04:19:21.313+0000] {warnings.py:110} WARNING - /home/***/.local/lib/python3.12/site-packages/***/task/task_runner/standard_task_runner.py:61: DeprecationWarning: This process (pid=4250) is multi-threaded, use of fork() may lead to deadlocks in the child.
  pid = os.fork()

[2024-11-14T04:19:21.328+0000] {standard_task_runner.py:63} INFO - Started process 4252 to run task
[2024-11-14T04:19:21.337+0000] {standard_task_runner.py:90} INFO - Running: ['***', 'tasks', 'run', 'BuildELT_dbt', 'dbt_run', 'manual__2024-11-14T04:19:18.165294+00:00', '--job-id', '215', '--raw', '--subdir', 'DAGS_FOLDER/build_elt_with_dbt.py', '--cfg-path', '/tmp/tmp3pbm06hv']
[2024-11-14T04:19:21.378+0000] {standard_task_runner.py:91} INFO - Job 215: Subtask dbt_run
[2024-11-14T04:19:21.586+0000] {task_command.py:426} INFO - Running <TaskInstance: BuildELT_dbt.dbt_run manual__2024-11-14T04:19:18.165294+00:00 [running]> on host 3627cdc70e56
[2024-11-14T04:19:22.011+0000] {taskinstance.py:2648} INFO - Exporting env vars: AIRFLOW_CTX_DAG_OWNER='***' AIRFLOW_CTX_DAG_ID='BuildELT_dbt' AIRFLOW_CTX_TASK_ID='dbt_run' AIRFLOW_CTX_EXECUTION_DATE='2024-11-14T04:19:18.165294+00:00' AIRFLOW_CTX_TRY_NUMBER='1' AIRFLOW_CTX_DAG_RUN_ID='manual__2024-11-14T04:19:18.165294+00:00'
[2024-11-14T04:19:22.044+0000] {taskinstance.py:430} INFO - ::endgroup::
[2024-11-14T04:19:22.051+0000] {subprocess.py:63} INFO - Tmp dir root location: /tmp
[2024-11-14T04:19:22.056+0000] {subprocess.py:75} INFO - Running command: ['/usr/bin/bash', '-c', '/home/***/.local/bin/dbt run --profiles-dir /opt/***/build_dbt --project-dir /opt/***/build_dbt']
[2024-11-14T04:19:22.184+0000] {subprocess.py:86} INFO - Output:
[2024-11-14T04:19:24.917+0000] {subprocess.py:93} INFO - [0m04:19:24  Running with dbt=1.8.7
[2024-11-14T04:19:26.045+0000] {subprocess.py:93} INFO - [0m04:19:26  Registered adapter: snowflake=1.8.4
[2024-11-14T04:19:26.870+0000] {subprocess.py:93} INFO - [0m04:19:26  [[33mWARNING[0m]: Configuration paths exist in your dbt_project.yml file which do not apply to any resources.
[2024-11-14T04:19:26.883+0000] {subprocess.py:93} INFO - There are 1 unused configuration paths:
[2024-11-14T04:19:26.887+0000] {subprocess.py:93} INFO - - models.build_dbt.example
[2024-11-14T04:19:27.142+0000] {subprocess.py:93} INFO - [0m04:19:27  Found 4 models, 1 snapshot, 2 sources, 459 macros
[2024-11-14T04:19:27.153+0000] {subprocess.py:93} INFO - [0m04:19:27
[2024-11-14T04:19:32.139+0000] {subprocess.py:93} INFO - [0m04:19:32  Concurrency: 1 threads (target='dev')
[2024-11-14T04:19:32.151+0000] {subprocess.py:93} INFO - [0m04:19:32
[2024-11-14T04:19:32.183+0000] {subprocess.py:93} INFO - [0m04:19:32  1 of 4 START sql table model analytics.moving_average .......................... [RUN]
[2024-11-14T04:19:34.339+0000] {subprocess.py:93} INFO - [0m04:19:34  1 of 4 OK created sql table model analytics.moving_average ..................... [[32mSUCCESS 1[0m in 2.14s]
[2024-11-14T04:19:34.352+0000] {subprocess.py:93} INFO - [0m04:19:34  2 of 4 START sql view model analytics.raw_stock_data ........................... [RUN]
[2024-11-14T04:19:36.127+0000] {subprocess.py:93} INFO - [0m04:19:36  2 of 4 OK created sql view model analytics.raw_stock_data ...................... [[32mSUCCESS 1[0m in 1.76s]
[2024-11-14T04:19:36.144+0000] {subprocess.py:93} INFO - [0m04:19:36  3 of 4 START sql view model analytics.rsi ...................................... [RUN]
[2024-11-14T04:19:38.053+0000] {subprocess.py:93} INFO - [0m04:19:38  3 of 4 OK created sql view model analytics.rsi ................................. [[32mSUCCESS 1[0m in 1.89s]
[2024-11-14T04:19:38.074+0000] {subprocess.py:93} INFO - [0m04:19:38  4 of 4 START sql table model analytics.stock_analytics ......................... [RUN]
[2024-11-14T04:19:39.782+0000] {subprocess.py:93} INFO - [0m04:19:39  4 of 4 ERROR creating sql table model analytics.stock_analytics ................ [[31mERROR[0m in 1.70s]
[2024-11-14T04:19:39.795+0000] {subprocess.py:93} INFO - [0m04:19:39
[2024-11-14T04:19:39.797+0000] {subprocess.py:93} INFO - [0m04:19:39  Finished running 2 table models, 2 view models in 0 hours 0 minutes and 12.64 seconds (12.64s).
[2024-11-14T04:19:39.897+0000] {subprocess.py:93} INFO - [0m04:19:39
[2024-11-14T04:19:39.899+0000] {subprocess.py:93} INFO - [0m04:19:39  [31mCompleted with 1 error and 0 warnings:[0m
[2024-11-14T04:19:39.900+0000] {subprocess.py:93} INFO - [0m04:19:39
[2024-11-14T04:19:39.902+0000] {subprocess.py:93} INFO - [0m04:19:39    Database Error in model stock_analytics (models/output/stock_analytics.sql)
[2024-11-14T04:19:39.903+0000] {subprocess.py:93} INFO -   000904 (42000): SQL compilation error: error line 13 at position 4
[2024-11-14T04:19:39.904+0000] {subprocess.py:93} INFO -   invalid identifier 'RSI.RSI'
[2024-11-14T04:19:39.904+0000] {subprocess.py:93} INFO -   compiled code at target/run/build_dbt/models/output/stock_analytics.sql
[2024-11-14T04:19:39.905+0000] {subprocess.py:93} INFO - [0m04:19:39
[2024-11-14T04:19:39.906+0000] {subprocess.py:93} INFO - [0m04:19:39  Done. PASS=3 WARN=0 ERROR=1 SKIP=0 TOTAL=4
[2024-11-14T04:19:40.732+0000] {subprocess.py:97} INFO - Command exited with return code 1
[2024-11-14T04:19:40.738+0000] {taskinstance.py:441} INFO - ::group::Post task execution logs
[2024-11-14T04:19:40.769+0000] {taskinstance.py:2905} ERROR - Task failed with exception
Traceback (most recent call last):
  File "/home/airflow/.local/lib/python3.12/site-packages/airflow/models/taskinstance.py", line 465, in _execute_task
    result = _execute_callable(context=context, **execute_callable_kwargs)
             ^^^^^^^^^^^^^^^^^^^^^^^^^^^^^^^^^^^^^^^^^^^^^^^^^^^^^^^^^^^^^
  File "/home/airflow/.local/lib/python3.12/site-packages/airflow/models/taskinstance.py", line 432, in _execute_callable
    return execute_callable(context=context, **execute_callable_kwargs)
           ^^^^^^^^^^^^^^^^^^^^^^^^^^^^^^^^^^^^^^^^^^^^^^^^^^^^^^^^^^^^
  File "/home/airflow/.local/lib/python3.12/site-packages/airflow/models/baseoperator.py", line 400, in wrapper
    return func(self, *args, **kwargs)
           ^^^^^^^^^^^^^^^^^^^^^^^^^^^
  File "/home/airflow/.local/lib/python3.12/site-packages/airflow/operators/bash.py", line 243, in execute
    raise AirflowException(
airflow.exceptions.AirflowException: Bash command failed. The command returned a non-zero exit code 1.
[2024-11-14T04:19:40.782+0000] {taskinstance.py:1206} INFO - Marking task as FAILED. dag_id=BuildELT_dbt, task_id=dbt_run, run_id=manual__2024-11-14T04:19:18.165294+00:00, execution_date=20241114T041918, start_date=20241114T041921, end_date=20241114T041940
[2024-11-14T04:19:40.802+0000] {standard_task_runner.py:110} ERROR - Failed to execute job 215 for task dbt_run (Bash command failed. The command returned a non-zero exit code 1.; 4252)
[2024-11-14T04:19:40.859+0000] {local_task_job_runner.py:240} INFO - Task exited with return code 1
[2024-11-14T04:19:40.909+0000] {taskinstance.py:3498} INFO - 0 downstream tasks scheduled from follow-on schedule check
[2024-11-14T04:19:40.916+0000] {local_task_job_runner.py:222} INFO - ::endgroup::
