[2024-11-14T04:11:07.663+0000] {local_task_job_runner.py:120} INFO - ::group::Pre task execution logs
[2024-11-14T04:11:07.680+0000] {taskinstance.py:2076} INFO - Dependencies all met for dep_context=non-requeueable deps ti=<TaskInstance: BuildELT_dbt.dbt_run manual__2024-11-14T04:11:04.234677+00:00 [queued]>
[2024-11-14T04:11:07.685+0000] {taskinstance.py:2076} INFO - Dependencies all met for dep_context=requeueable deps ti=<TaskInstance: BuildELT_dbt.dbt_run manual__2024-11-14T04:11:04.234677+00:00 [queued]>
[2024-11-14T04:11:07.686+0000] {taskinstance.py:2306} INFO - Starting attempt 1 of 1
[2024-11-14T04:11:07.694+0000] {taskinstance.py:2330} INFO - Executing <Task(BashOperator): dbt_run> on 2024-11-14 04:11:04.234677+00:00
[2024-11-14T04:11:07.709+0000] {warnings.py:110} WARNING - /home/***/.local/lib/python3.12/site-packages/***/task/task_runner/standard_task_runner.py:61: DeprecationWarning: This process (pid=4090) is multi-threaded, use of fork() may lead to deadlocks in the child.
  pid = os.fork()

[2024-11-14T04:11:07.712+0000] {standard_task_runner.py:63} INFO - Started process 4092 to run task
[2024-11-14T04:11:07.712+0000] {standard_task_runner.py:90} INFO - Running: ['***', 'tasks', 'run', 'BuildELT_dbt', 'dbt_run', 'manual__2024-11-14T04:11:04.234677+00:00', '--job-id', '213', '--raw', '--subdir', 'DAGS_FOLDER/build_elt_with_dbt.py', '--cfg-path', '/tmp/tmpjhjzkwb2']
[2024-11-14T04:11:07.715+0000] {standard_task_runner.py:91} INFO - Job 213: Subtask dbt_run
[2024-11-14T04:11:07.760+0000] {task_command.py:426} INFO - Running <TaskInstance: BuildELT_dbt.dbt_run manual__2024-11-14T04:11:04.234677+00:00 [running]> on host 3627cdc70e56
[2024-11-14T04:11:07.847+0000] {taskinstance.py:2648} INFO - Exporting env vars: AIRFLOW_CTX_DAG_OWNER='***' AIRFLOW_CTX_DAG_ID='BuildELT_dbt' AIRFLOW_CTX_TASK_ID='dbt_run' AIRFLOW_CTX_EXECUTION_DATE='2024-11-14T04:11:04.234677+00:00' AIRFLOW_CTX_TRY_NUMBER='1' AIRFLOW_CTX_DAG_RUN_ID='manual__2024-11-14T04:11:04.234677+00:00'
[2024-11-14T04:11:07.850+0000] {taskinstance.py:430} INFO - ::endgroup::
[2024-11-14T04:11:07.852+0000] {subprocess.py:63} INFO - Tmp dir root location: /tmp
[2024-11-14T04:11:07.854+0000] {subprocess.py:75} INFO - Running command: ['/usr/bin/bash', '-c', '/home/***/.local/bin/dbt run --profiles-dir /opt/***/build_dbt --project-dir /opt/***/build_dbt']
[2024-11-14T04:11:07.866+0000] {subprocess.py:86} INFO - Output:
[2024-11-14T04:11:10.000+0000] {subprocess.py:93} INFO - [0m04:11:09  Running with dbt=1.8.7
[2024-11-14T04:11:11.657+0000] {subprocess.py:93} INFO - [0m04:11:11  Registered adapter: snowflake=1.8.4
[2024-11-14T04:11:12.146+0000] {subprocess.py:93} INFO - [0m04:11:12  [[33mWARNING[0m]: Configuration paths exist in your dbt_project.yml file which do not apply to any resources.
[2024-11-14T04:11:12.148+0000] {subprocess.py:93} INFO - There are 1 unused configuration paths:
[2024-11-14T04:11:12.149+0000] {subprocess.py:93} INFO - - models.build_dbt.example
[2024-11-14T04:11:12.438+0000] {subprocess.py:93} INFO - [0m04:11:12  Found 4 models, 1 snapshot, 2 sources, 459 macros
[2024-11-14T04:11:12.445+0000] {subprocess.py:93} INFO - [0m04:11:12
[2024-11-14T04:11:18.079+0000] {subprocess.py:93} INFO - [0m04:11:18  Concurrency: 1 threads (target='dev')
[2024-11-14T04:11:18.088+0000] {subprocess.py:93} INFO - [0m04:11:18
[2024-11-14T04:11:18.125+0000] {subprocess.py:93} INFO - [0m04:11:18  1 of 4 START sql table model analytics.moving_average .......................... [RUN]
[2024-11-14T04:11:21.512+0000] {subprocess.py:93} INFO - [0m04:11:21  1 of 4 OK created sql table model analytics.moving_average ..................... [[32mSUCCESS 1[0m in 3.32s]
[2024-11-14T04:11:21.553+0000] {subprocess.py:93} INFO - [0m04:11:21  2 of 4 START sql view model analytics.raw_stock_data ........................... [RUN]
[2024-11-14T04:11:23.502+0000] {subprocess.py:93} INFO - [0m04:11:23  2 of 4 OK created sql view model analytics.raw_stock_data ...................... [[32mSUCCESS 1[0m in 1.92s]
[2024-11-14T04:11:23.521+0000] {subprocess.py:93} INFO - [0m04:11:23  3 of 4 START sql view model analytics.rsi ...................................... [RUN]
[2024-11-14T04:11:25.439+0000] {subprocess.py:93} INFO - [0m04:11:25  3 of 4 ERROR creating sql view model analytics.rsi ............................. [[31mERROR[0m in 1.91s]
[2024-11-14T04:11:25.455+0000] {subprocess.py:93} INFO - [0m04:11:25  4 of 4 SKIP relation analytics.stock_analytics ................................. [[33mSKIP[0m]
[2024-11-14T04:11:25.472+0000] {subprocess.py:93} INFO - [0m04:11:25
[2024-11-14T04:11:25.477+0000] {subprocess.py:93} INFO - [0m04:11:25  Finished running 2 table models, 2 view models in 0 hours 0 minutes and 13.02 seconds (13.02s).
[2024-11-14T04:11:25.691+0000] {subprocess.py:93} INFO - [0m04:11:25
[2024-11-14T04:11:25.694+0000] {subprocess.py:93} INFO - [0m04:11:25  [31mCompleted with 1 error and 0 warnings:[0m
[2024-11-14T04:11:25.701+0000] {subprocess.py:93} INFO - [0m04:11:25
[2024-11-14T04:11:25.706+0000] {subprocess.py:93} INFO - [0m04:11:25    Database Error in model rsi (models/output/rsi.sql)
[2024-11-14T04:11:25.708+0000] {subprocess.py:93} INFO -   001003 (42000): SQL compilation error:
[2024-11-14T04:11:25.711+0000] {subprocess.py:93} INFO -   syntax error line 53 at position 21 unexpected ';'.
[2024-11-14T04:11:25.717+0000] {subprocess.py:93} INFO -   compiled code at target/run/build_dbt/models/output/rsi.sql
[2024-11-14T04:11:25.722+0000] {subprocess.py:93} INFO - [0m04:11:25
[2024-11-14T04:11:25.725+0000] {subprocess.py:93} INFO - [0m04:11:25  Done. PASS=2 WARN=0 ERROR=1 SKIP=1 TOTAL=4
[2024-11-14T04:11:27.538+0000] {subprocess.py:97} INFO - Command exited with return code 1
[2024-11-14T04:11:27.557+0000] {taskinstance.py:441} INFO - ::group::Post task execution logs
[2024-11-14T04:11:27.614+0000] {taskinstance.py:2905} ERROR - Task failed with exception
Traceback (most recent call last):
  File "/home/airflow/.local/lib/python3.12/site-packages/airflow/models/taskinstance.py", line 465, in _execute_task
    result = _execute_callable(context=context, **execute_callable_kwargs)
             ^^^^^^^^^^^^^^^^^^^^^^^^^^^^^^^^^^^^^^^^^^^^^^^^^^^^^^^^^^^^^
  File "/home/airflow/.local/lib/python3.12/site-packages/airflow/models/taskinstance.py", line 432, in _execute_callable
    return execute_callable(context=context, **execute_callable_kwargs)
           ^^^^^^^^^^^^^^^^^^^^^^^^^^^^^^^^^^^^^^^^^^^^^^^^^^^^^^^^^^^^
  File "/home/airflow/.local/lib/python3.12/site-packages/airflow/models/baseoperator.py", line 400, in wrapper
    return func(self, *args, **kwargs)
           ^^^^^^^^^^^^^^^^^^^^^^^^^^^
  File "/home/airflow/.local/lib/python3.12/site-packages/airflow/operators/bash.py", line 243, in execute
    raise AirflowException(
airflow.exceptions.AirflowException: Bash command failed. The command returned a non-zero exit code 1.
[2024-11-14T04:11:27.631+0000] {taskinstance.py:1206} INFO - Marking task as FAILED. dag_id=BuildELT_dbt, task_id=dbt_run, run_id=manual__2024-11-14T04:11:04.234677+00:00, execution_date=20241114T041104, start_date=20241114T041107, end_date=20241114T041127
[2024-11-14T04:11:27.662+0000] {standard_task_runner.py:110} ERROR - Failed to execute job 213 for task dbt_run (Bash command failed. The command returned a non-zero exit code 1.; 4092)
[2024-11-14T04:11:27.742+0000] {local_task_job_runner.py:240} INFO - Task exited with return code 1
[2024-11-14T04:11:27.821+0000] {taskinstance.py:3498} INFO - 0 downstream tasks scheduled from follow-on schedule check
[2024-11-14T04:11:27.848+0000] {local_task_job_runner.py:222} INFO - ::endgroup::
