[2024-11-20T21:19:12.412+0000] {task_context_logger.py:104} WARNING - Marking task instance <TaskInstance: stockprices_v2_decorator.extract__1 scheduled__2024-11-20T18:10:00+00:00 [queued]> stuck in queued as failed. If the task instance has available retries, it will be retried.
[2024-11-20T21:19:22.697+0000] {task_context_logger.py:104} ERROR - Executor reports task instance <TaskInstance: stockprices_v2_decorator.extract__1 scheduled__2024-11-20T18:10:00+00:00 [queued]> finished (failed) although the task says it's queued. (Info: None) Was the task killed externally?
