[2024-11-13T01:36:36.245+0000] {local_task_job_runner.py:120} INFO - ::group::Pre task execution logs
[2024-11-13T01:36:36.259+0000] {taskinstance.py:2076} INFO - Dependencies all met for dep_context=non-requeueable deps ti=<TaskInstance: PopulationDataToSnowflake.load_population_data scheduled__2024-11-11T02:30:00+00:00 [queued]>
[2024-11-13T01:36:36.265+0000] {taskinstance.py:2076} INFO - Dependencies all met for dep_context=requeueable deps ti=<TaskInstance: PopulationDataToSnowflake.load_population_data scheduled__2024-11-11T02:30:00+00:00 [queued]>
[2024-11-13T01:36:36.266+0000] {taskinstance.py:2306} INFO - Starting attempt 1 of 1
[2024-11-13T01:36:36.272+0000] {taskinstance.py:2330} INFO - Executing <Task(_PythonDecoratedOperator): load_population_data> on 2024-11-11 02:30:00+00:00
[2024-11-13T01:36:36.292+0000] {warnings.py:110} WARNING - /home/***/.local/lib/python3.12/site-packages/***/task/task_runner/standard_task_runner.py:61: DeprecationWarning: This process (pid=116) is multi-threaded, use of fork() may lead to deadlocks in the child.
  pid = os.fork()

[2024-11-13T01:36:36.295+0000] {standard_task_runner.py:63} INFO - Started process 118 to run task
[2024-11-13T01:36:36.295+0000] {standard_task_runner.py:90} INFO - Running: ['***', 'tasks', 'run', 'PopulationDataToSnowflake', 'load_population_data', 'scheduled__2024-11-11T02:30:00+00:00', '--job-id', '4', '--raw', '--subdir', 'DAGS_FOLDER/PopulationDataToSnowflake.py', '--cfg-path', '/tmp/tmphqd2reph']
[2024-11-13T01:36:36.298+0000] {standard_task_runner.py:91} INFO - Job 4: Subtask load_population_data
[2024-11-13T01:36:36.335+0000] {task_command.py:426} INFO - Running <TaskInstance: PopulationDataToSnowflake.load_population_data scheduled__2024-11-11T02:30:00+00:00 [running]> on host 712e3f8fee64
[2024-11-13T01:36:36.400+0000] {taskinstance.py:2648} INFO - Exporting env vars: AIRFLOW_CTX_DAG_OWNER='***' AIRFLOW_CTX_DAG_ID='PopulationDataToSnowflake' AIRFLOW_CTX_TASK_ID='load_population_data' AIRFLOW_CTX_EXECUTION_DATE='2024-11-11T02:30:00+00:00' AIRFLOW_CTX_TRY_NUMBER='1' AIRFLOW_CTX_DAG_RUN_ID='scheduled__2024-11-11T02:30:00+00:00'
[2024-11-13T01:36:36.404+0000] {taskinstance.py:430} INFO - ::endgroup::
[2024-11-13T01:36:36.412+0000] {taskinstance.py:441} INFO - ::group::Post task execution logs
[2024-11-13T01:36:36.420+0000] {taskinstance.py:2905} ERROR - Task failed with exception
Traceback (most recent call last):
  File "/home/airflow/.local/lib/python3.12/site-packages/airflow/models/taskinstance.py", line 465, in _execute_task
    result = _execute_callable(context=context, **execute_callable_kwargs)
             ^^^^^^^^^^^^^^^^^^^^^^^^^^^^^^^^^^^^^^^^^^^^^^^^^^^^^^^^^^^^^
  File "/home/airflow/.local/lib/python3.12/site-packages/airflow/models/taskinstance.py", line 432, in _execute_callable
    return execute_callable(context=context, **execute_callable_kwargs)
           ^^^^^^^^^^^^^^^^^^^^^^^^^^^^^^^^^^^^^^^^^^^^^^^^^^^^^^^^^^^^
  File "/home/airflow/.local/lib/python3.12/site-packages/airflow/models/baseoperator.py", line 400, in wrapper
    return func(self, *args, **kwargs)
           ^^^^^^^^^^^^^^^^^^^^^^^^^^^
  File "/home/airflow/.local/lib/python3.12/site-packages/airflow/decorators/base.py", line 265, in execute
    return_value = super().execute(context)
                   ^^^^^^^^^^^^^^^^^^^^^^^^
  File "/home/airflow/.local/lib/python3.12/site-packages/airflow/models/baseoperator.py", line 400, in wrapper
    return func(self, *args, **kwargs)
           ^^^^^^^^^^^^^^^^^^^^^^^^^^^
  File "/home/airflow/.local/lib/python3.12/site-packages/airflow/operators/python.py", line 235, in execute
    return_value = self.execute_callable()
                   ^^^^^^^^^^^^^^^^^^^^^^^
  File "/home/airflow/.local/lib/python3.12/site-packages/airflow/operators/python.py", line 252, in execute_callable
    return self.python_callable(*self.op_args, **self.op_kwargs)
           ^^^^^^^^^^^^^^^^^^^^^^^^^^^^^^^^^^^^^^^^^^^^^^^^^^^^^
  File "/opt/airflow/dags/PopulationDataToSnowflake.py", line 67, in load_population_data
    cur = return_snowflake_conn()
          ^^^^^^^^^^^^^^^^^^^^^^^
  File "/opt/airflow/dags/PopulationDataToSnowflake.py", line 23, in return_snowflake_conn
    conn = hook.get_conn()
           ^^^^^^^^^^^^^^^
  File "/home/airflow/.local/lib/python3.12/site-packages/airflow/providers/snowflake/hooks/snowflake.py", line 286, in get_conn
    conn_config = self._get_conn_params()
                  ^^^^^^^^^^^^^^^^^^^^^^^
  File "/home/airflow/.local/lib/python3.12/site-packages/airflow/providers/snowflake/hooks/snowflake.py", line 185, in _get_conn_params
    conn = self.get_connection(self.snowflake_conn_id)  # type: ignore[attr-defined]
           ^^^^^^^^^^^^^^^^^^^^^^^^^^^^^^^^^^^^^^^^^^^
  File "/home/airflow/.local/lib/python3.12/site-packages/airflow/hooks/base.py", line 83, in get_connection
    conn = Connection.get_connection_from_secrets(conn_id)
           ^^^^^^^^^^^^^^^^^^^^^^^^^^^^^^^^^^^^^^^^^^^^^^^
  File "/home/airflow/.local/lib/python3.12/site-packages/airflow/models/connection.py", line 519, in get_connection_from_secrets
    raise AirflowNotFoundException(f"The conn_id `{conn_id}` isn't defined")
airflow.exceptions.AirflowNotFoundException: The conn_id `snowflake_conn` isn't defined
[2024-11-13T01:36:36.427+0000] {taskinstance.py:1206} INFO - Marking task as FAILED. dag_id=PopulationDataToSnowflake, task_id=load_population_data, run_id=scheduled__2024-11-11T02:30:00+00:00, execution_date=20241111T023000, start_date=20241113T013636, end_date=20241113T013636
[2024-11-13T01:36:36.435+0000] {standard_task_runner.py:110} ERROR - Failed to execute job 4 for task load_population_data (The conn_id `snowflake_conn` isn't defined; 118)
[2024-11-13T01:36:36.471+0000] {local_task_job_runner.py:240} INFO - Task exited with return code 1
[2024-11-13T01:36:36.488+0000] {taskinstance.py:3498} INFO - 0 downstream tasks scheduled from follow-on schedule check
[2024-11-13T01:36:36.490+0000] {local_task_job_runner.py:222} INFO - ::endgroup::
