[2024-11-17T23:39:52.298+0000] {task_context_logger.py:104} WARNING - Marking task instance <TaskInstance: stockprices_v2_decorator.extract scheduled__2024-11-17T21:20:00+00:00 [queued]> stuck in queued as failed. If the task instance has available retries, it will be retried.
[2024-11-17T23:40:00.760+0000] {task_context_logger.py:104} ERROR - Executor reports task instance <TaskInstance: stockprices_v2_decorator.extract scheduled__2024-11-17T21:20:00+00:00 [queued]> finished (failed) although the task says it's queued. (Info: None) Was the task killed externally?
