[2024-11-14T04:05:30.957+0000] {local_task_job_runner.py:120} INFO - ::group::Pre task execution logs
[2024-11-14T04:05:30.979+0000] {taskinstance.py:2076} INFO - Dependencies all met for dep_context=non-requeueable deps ti=<TaskInstance: BuildELT_dbt.dbt_run manual__2024-11-14T04:05:27.701829+00:00 [queued]>
[2024-11-14T04:05:30.985+0000] {taskinstance.py:2076} INFO - Dependencies all met for dep_context=requeueable deps ti=<TaskInstance: BuildELT_dbt.dbt_run manual__2024-11-14T04:05:27.701829+00:00 [queued]>
[2024-11-14T04:05:30.986+0000] {taskinstance.py:2306} INFO - Starting attempt 1 of 1
[2024-11-14T04:05:30.995+0000] {taskinstance.py:2330} INFO - Executing <Task(BashOperator): dbt_run> on 2024-11-14 04:05:27.701829+00:00
[2024-11-14T04:05:31.007+0000] {warnings.py:110} WARNING - /home/***/.local/lib/python3.12/site-packages/***/task/task_runner/standard_task_runner.py:61: DeprecationWarning: This process (pid=3948) is multi-threaded, use of fork() may lead to deadlocks in the child.
  pid = os.fork()

[2024-11-14T04:05:31.009+0000] {standard_task_runner.py:63} INFO - Started process 3950 to run task
[2024-11-14T04:05:31.010+0000] {standard_task_runner.py:90} INFO - Running: ['***', 'tasks', 'run', 'BuildELT_dbt', 'dbt_run', 'manual__2024-11-14T04:05:27.701829+00:00', '--job-id', '203', '--raw', '--subdir', 'DAGS_FOLDER/build_elt_with_dbt.py', '--cfg-path', '/tmp/tmp3tef9p7w']
[2024-11-14T04:05:31.013+0000] {standard_task_runner.py:91} INFO - Job 203: Subtask dbt_run
[2024-11-14T04:05:31.064+0000] {task_command.py:426} INFO - Running <TaskInstance: BuildELT_dbt.dbt_run manual__2024-11-14T04:05:27.701829+00:00 [running]> on host 3627cdc70e56
[2024-11-14T04:05:31.229+0000] {taskinstance.py:2648} INFO - Exporting env vars: AIRFLOW_CTX_DAG_OWNER='***' AIRFLOW_CTX_DAG_ID='BuildELT_dbt' AIRFLOW_CTX_TASK_ID='dbt_run' AIRFLOW_CTX_EXECUTION_DATE='2024-11-14T04:05:27.701829+00:00' AIRFLOW_CTX_TRY_NUMBER='1' AIRFLOW_CTX_DAG_RUN_ID='manual__2024-11-14T04:05:27.701829+00:00'
[2024-11-14T04:05:31.234+0000] {taskinstance.py:430} INFO - ::endgroup::
[2024-11-14T04:05:31.238+0000] {subprocess.py:63} INFO - Tmp dir root location: /tmp
[2024-11-14T04:05:31.243+0000] {subprocess.py:75} INFO - Running command: ['/usr/bin/bash', '-c', '/home/***/.local/bin/dbt run --profiles-dir /opt/***/build_dbt --project-dir /opt/***/build_dbt']
[2024-11-14T04:05:31.259+0000] {subprocess.py:86} INFO - Output:
[2024-11-14T04:05:33.632+0000] {subprocess.py:93} INFO - [0m04:05:33  Running with dbt=1.8.7
[2024-11-14T04:05:34.882+0000] {subprocess.py:93} INFO - [0m04:05:34  Registered adapter: snowflake=1.8.4
[2024-11-14T04:05:35.292+0000] {subprocess.py:93} INFO - [0m04:05:35  [[33mWARNING[0m]: Configuration paths exist in your dbt_project.yml file which do not apply to any resources.
[2024-11-14T04:05:35.296+0000] {subprocess.py:93} INFO - There are 1 unused configuration paths:
[2024-11-14T04:05:35.296+0000] {subprocess.py:93} INFO - - models.build_dbt.example
[2024-11-14T04:05:35.477+0000] {subprocess.py:93} INFO - [0m04:05:35  Found 4 models, 1 snapshot, 2 sources, 459 macros
[2024-11-14T04:05:35.486+0000] {subprocess.py:93} INFO - [0m04:05:35
[2024-11-14T04:05:40.712+0000] {subprocess.py:93} INFO - [0m04:05:40  Concurrency: 1 threads (target='dev')
[2024-11-14T04:05:40.723+0000] {subprocess.py:93} INFO - [0m04:05:40
[2024-11-14T04:05:40.756+0000] {subprocess.py:93} INFO - [0m04:05:40  1 of 4 START sql table model analytics.moving_average .......................... [RUN]
[2024-11-14T04:05:42.918+0000] {subprocess.py:93} INFO - [0m04:05:42  1 of 4 OK created sql table model analytics.moving_average ..................... [[32mSUCCESS 1[0m in 2.15s]
[2024-11-14T04:05:42.928+0000] {subprocess.py:93} INFO - [0m04:05:42  2 of 4 START sql view model analytics.raw_stock_data ........................... [RUN]
[2024-11-14T04:05:44.605+0000] {subprocess.py:93} INFO - [0m04:05:44  2 of 4 OK created sql view model analytics.raw_stock_data ...................... [[32mSUCCESS 1[0m in 1.67s]
[2024-11-14T04:05:44.611+0000] {subprocess.py:93} INFO - [0m04:05:44  3 of 4 START sql view model analytics.rsi ...................................... [RUN]
[2024-11-14T04:05:46.122+0000] {subprocess.py:93} INFO - [0m04:05:46  3 of 4 ERROR creating sql view model analytics.rsi ............................. [[31mERROR[0m in 1.50s]
[2024-11-14T04:05:46.138+0000] {subprocess.py:93} INFO - [0m04:05:46  4 of 4 SKIP relation analytics.stock_analytics ................................. [[33mSKIP[0m]
[2024-11-14T04:05:46.154+0000] {subprocess.py:93} INFO - [0m04:05:46
[2024-11-14T04:05:46.160+0000] {subprocess.py:93} INFO - [0m04:05:46  Finished running 2 table models, 2 view models in 0 hours 0 minutes and 10.66 seconds (10.66s).
[2024-11-14T04:05:46.394+0000] {subprocess.py:93} INFO - [0m04:05:46
[2024-11-14T04:05:46.398+0000] {subprocess.py:93} INFO - [0m04:05:46  [31mCompleted with 1 error and 0 warnings:[0m
[2024-11-14T04:05:46.404+0000] {subprocess.py:93} INFO - [0m04:05:46
[2024-11-14T04:05:46.407+0000] {subprocess.py:93} INFO - [0m04:05:46    Database Error in model rsi (models/output/rsi.sql)
[2024-11-14T04:05:46.408+0000] {subprocess.py:93} INFO -   001003 (42000): SQL compilation error:
[2024-11-14T04:05:46.410+0000] {subprocess.py:93} INFO -   syntax error line 53 at position 21 unexpected ';'.
[2024-11-14T04:05:46.412+0000] {subprocess.py:93} INFO -   compiled code at target/run/build_dbt/models/output/rsi.sql
[2024-11-14T04:05:46.414+0000] {subprocess.py:93} INFO - [0m04:05:46
[2024-11-14T04:05:46.415+0000] {subprocess.py:93} INFO - [0m04:05:46  Done. PASS=2 WARN=0 ERROR=1 SKIP=1 TOTAL=4
[2024-11-14T04:05:47.626+0000] {subprocess.py:97} INFO - Command exited with return code 1
[2024-11-14T04:05:47.639+0000] {taskinstance.py:441} INFO - ::group::Post task execution logs
[2024-11-14T04:05:47.705+0000] {taskinstance.py:2905} ERROR - Task failed with exception
Traceback (most recent call last):
  File "/home/airflow/.local/lib/python3.12/site-packages/airflow/models/taskinstance.py", line 465, in _execute_task
    result = _execute_callable(context=context, **execute_callable_kwargs)
             ^^^^^^^^^^^^^^^^^^^^^^^^^^^^^^^^^^^^^^^^^^^^^^^^^^^^^^^^^^^^^
  File "/home/airflow/.local/lib/python3.12/site-packages/airflow/models/taskinstance.py", line 432, in _execute_callable
    return execute_callable(context=context, **execute_callable_kwargs)
           ^^^^^^^^^^^^^^^^^^^^^^^^^^^^^^^^^^^^^^^^^^^^^^^^^^^^^^^^^^^^
  File "/home/airflow/.local/lib/python3.12/site-packages/airflow/models/baseoperator.py", line 400, in wrapper
    return func(self, *args, **kwargs)
           ^^^^^^^^^^^^^^^^^^^^^^^^^^^
  File "/home/airflow/.local/lib/python3.12/site-packages/airflow/operators/bash.py", line 243, in execute
    raise AirflowException(
airflow.exceptions.AirflowException: Bash command failed. The command returned a non-zero exit code 1.
[2024-11-14T04:05:47.726+0000] {taskinstance.py:1206} INFO - Marking task as FAILED. dag_id=BuildELT_dbt, task_id=dbt_run, run_id=manual__2024-11-14T04:05:27.701829+00:00, execution_date=20241114T040527, start_date=20241114T040530, end_date=20241114T040547
[2024-11-14T04:05:47.754+0000] {standard_task_runner.py:110} ERROR - Failed to execute job 203 for task dbt_run (Bash command failed. The command returned a non-zero exit code 1.; 3950)
[2024-11-14T04:05:47.845+0000] {local_task_job_runner.py:240} INFO - Task exited with return code 1
[2024-11-14T04:05:47.904+0000] {taskinstance.py:3498} INFO - 0 downstream tasks scheduled from follow-on schedule check
[2024-11-14T04:05:47.910+0000] {local_task_job_runner.py:222} INFO - ::endgroup::
