[2024-11-14T00:39:25.673+0000] {local_task_job_runner.py:120} INFO - ::group::Pre task execution logs
[2024-11-14T00:39:25.738+0000] {taskinstance.py:2076} INFO - Dependencies all met for dep_context=non-requeueable deps ti=<TaskInstance: PopulationDataToSnowflake.load_population_data__2 manual__2024-11-14T00:38:57.534972+00:00 [queued]>
[2024-11-14T00:39:25.765+0000] {taskinstance.py:2076} INFO - Dependencies all met for dep_context=requeueable deps ti=<TaskInstance: PopulationDataToSnowflake.load_population_data__2 manual__2024-11-14T00:38:57.534972+00:00 [queued]>
[2024-11-14T00:39:25.772+0000] {taskinstance.py:2306} INFO - Starting attempt 1 of 1
[2024-11-14T00:39:25.828+0000] {taskinstance.py:2330} INFO - Executing <Task(_PythonDecoratedOperator): load_population_data__2> on 2024-11-14 00:38:57.534972+00:00
[2024-11-14T00:39:25.868+0000] {warnings.py:110} WARNING - /home/***/.local/lib/python3.12/site-packages/***/task/task_runner/standard_task_runner.py:61: DeprecationWarning: This process (pid=865) is multi-threaded, use of fork() may lead to deadlocks in the child.
  pid = os.fork()

[2024-11-14T00:39:25.874+0000] {standard_task_runner.py:63} INFO - Started process 874 to run task
[2024-11-14T00:39:25.873+0000] {standard_task_runner.py:90} INFO - Running: ['***', 'tasks', 'run', 'PopulationDataToSnowflake', 'load_population_data__2', 'manual__2024-11-14T00:38:57.534972+00:00', '--job-id', '51', '--raw', '--subdir', 'DAGS_FOLDER/PopulationDataToSnowflake.py', '--cfg-path', '/tmp/tmplyh1k2be']
[2024-11-14T00:39:25.886+0000] {standard_task_runner.py:91} INFO - Job 51: Subtask load_population_data__2
[2024-11-14T00:39:26.028+0000] {task_command.py:426} INFO - Running <TaskInstance: PopulationDataToSnowflake.load_population_data__2 manual__2024-11-14T00:38:57.534972+00:00 [running]> on host 3627cdc70e56
[2024-11-14T00:39:26.464+0000] {taskinstance.py:2648} INFO - Exporting env vars: AIRFLOW_CTX_DAG_OWNER='***' AIRFLOW_CTX_DAG_ID='PopulationDataToSnowflake' AIRFLOW_CTX_TASK_ID='load_population_data__2' AIRFLOW_CTX_EXECUTION_DATE='2024-11-14T00:38:57.534972+00:00' AIRFLOW_CTX_TRY_NUMBER='1' AIRFLOW_CTX_DAG_RUN_ID='manual__2024-11-14T00:38:57.534972+00:00'
[2024-11-14T00:39:26.468+0000] {taskinstance.py:430} INFO - ::endgroup::
[2024-11-14T00:39:26.490+0000] {base.py:84} INFO - Using connection ID 'snowflake_conn' for task execution.
[2024-11-14T00:39:26.493+0000] {connection.py:399} INFO - Snowflake Connector for Python Version: 3.10.0, Python Version: 3.12.3, Platform: Linux-5.10.25-linuxkit-aarch64-with-glibc2.36
[2024-11-14T00:39:26.496+0000] {connection.py:1239} INFO - This connection is in OCSP Fail Open Mode. TLS Certificates would be checked for validity and revocation status. Any other Certificate Revocation related exceptions or OCSP Responder failures would be disregarded in favor of connectivity.
[2024-11-14T00:39:27.771+0000] {cursor.py:1149} INFO - Number of results in first chunk: 1
[2024-11-14T00:39:28.029+0000] {cursor.py:1149} INFO - Number of results in first chunk: 1
[2024-11-14T00:39:28.555+0000] {cursor.py:1149} INFO - Number of results in first chunk: 1
[2024-11-14T00:39:28.564+0000] {logging_mixin.py:188} INFO - Error loading data: 001003 (42000): 01b85ac7-0000-1aab-0000-370d00011cfe: SQL compilation error:
syntax error line 3 at position 12 unexpected 'ON'.
[2024-11-14T00:39:28.584+0000] {taskinstance.py:441} INFO - ::group::Post task execution logs
[2024-11-14T00:39:28.594+0000] {taskinstance.py:2905} ERROR - Task failed with exception
Traceback (most recent call last):
  File "/home/airflow/.local/lib/python3.12/site-packages/airflow/models/taskinstance.py", line 465, in _execute_task
    result = _execute_callable(context=context, **execute_callable_kwargs)
             ^^^^^^^^^^^^^^^^^^^^^^^^^^^^^^^^^^^^^^^^^^^^^^^^^^^^^^^^^^^^^
  File "/home/airflow/.local/lib/python3.12/site-packages/airflow/models/taskinstance.py", line 432, in _execute_callable
    return execute_callable(context=context, **execute_callable_kwargs)
           ^^^^^^^^^^^^^^^^^^^^^^^^^^^^^^^^^^^^^^^^^^^^^^^^^^^^^^^^^^^^
  File "/home/airflow/.local/lib/python3.12/site-packages/airflow/models/baseoperator.py", line 400, in wrapper
    return func(self, *args, **kwargs)
           ^^^^^^^^^^^^^^^^^^^^^^^^^^^
  File "/home/airflow/.local/lib/python3.12/site-packages/airflow/decorators/base.py", line 265, in execute
    return_value = super().execute(context)
                   ^^^^^^^^^^^^^^^^^^^^^^^^
  File "/home/airflow/.local/lib/python3.12/site-packages/airflow/models/baseoperator.py", line 400, in wrapper
    return func(self, *args, **kwargs)
           ^^^^^^^^^^^^^^^^^^^^^^^^^^^
  File "/home/airflow/.local/lib/python3.12/site-packages/airflow/operators/python.py", line 235, in execute
    return_value = self.execute_callable()
                   ^^^^^^^^^^^^^^^^^^^^^^^
  File "/home/airflow/.local/lib/python3.12/site-packages/airflow/operators/python.py", line 252, in execute_callable
    return self.python_callable(*self.op_args, **self.op_kwargs)
           ^^^^^^^^^^^^^^^^^^^^^^^^^^^^^^^^^^^^^^^^^^^^^^^^^^^^^
  File "/opt/airflow/dags/PopulationDataToSnowflake.py", line 103, in load_population_data
    raise e
  File "/opt/airflow/dags/PopulationDataToSnowflake.py", line 93, in load_population_data
    cur.execute(sql, (record['country'], record['year'], record['population']))
  File "/home/airflow/.local/lib/python3.12/site-packages/snowflake/connector/cursor.py", line 1080, in execute
    Error.errorhandler_wrapper(self.connection, self, error_class, errvalue)
  File "/home/airflow/.local/lib/python3.12/site-packages/snowflake/connector/errors.py", line 290, in errorhandler_wrapper
    handed_over = Error.hand_to_other_handler(
                  ^^^^^^^^^^^^^^^^^^^^^^^^^^^^
  File "/home/airflow/.local/lib/python3.12/site-packages/snowflake/connector/errors.py", line 345, in hand_to_other_handler
    cursor.errorhandler(connection, cursor, error_class, error_value)
  File "/home/airflow/.local/lib/python3.12/site-packages/snowflake/connector/errors.py", line 221, in default_errorhandler
    raise error_class(
snowflake.connector.errors.ProgrammingError: 001003 (42000): 01b85ac7-0000-1aab-0000-370d00011cfe: SQL compilation error:
syntax error line 3 at position 12 unexpected 'ON'.
[2024-11-14T00:39:28.632+0000] {taskinstance.py:1206} INFO - Marking task as FAILED. dag_id=PopulationDataToSnowflake, task_id=load_population_data__2, run_id=manual__2024-11-14T00:38:57.534972+00:00, execution_date=20241114T003857, start_date=20241114T003925, end_date=20241114T003928
[2024-11-14T00:39:28.694+0000] {standard_task_runner.py:110} ERROR - Failed to execute job 51 for task load_population_data__2 (001003 (42000): 01b85ac7-0000-1aab-0000-370d00011cfe: SQL compilation error:
syntax error line 3 at position 12 unexpected 'ON'.; 874)
[2024-11-14T00:39:28.866+0000] {local_task_job_runner.py:240} INFO - Task exited with return code 1
[2024-11-14T00:39:28.939+0000] {local_task_job_runner.py:222} INFO - ::endgroup::
