[2024-11-14T03:47:22.439+0000] {local_task_job_runner.py:120} INFO - ::group::Pre task execution logs
[2024-11-14T03:47:22.507+0000] {taskinstance.py:2076} INFO - Dependencies all met for dep_context=non-requeueable deps ti=<TaskInstance: BuildELT_dbt.dbt_run manual__2024-11-14T03:47:18.639970+00:00 [queued]>
[2024-11-14T03:47:22.532+0000] {taskinstance.py:2076} INFO - Dependencies all met for dep_context=requeueable deps ti=<TaskInstance: BuildELT_dbt.dbt_run manual__2024-11-14T03:47:18.639970+00:00 [queued]>
[2024-11-14T03:47:22.536+0000] {taskinstance.py:2306} INFO - Starting attempt 1 of 1
[2024-11-14T03:47:22.603+0000] {taskinstance.py:2330} INFO - Executing <Task(BashOperator): dbt_run> on 2024-11-14 03:47:18.639970+00:00
[2024-11-14T03:47:22.691+0000] {warnings.py:110} WARNING - /home/***/.local/lib/python3.12/site-packages/***/task/task_runner/standard_task_runner.py:61: DeprecationWarning: This process (pid=3600) is multi-threaded, use of fork() may lead to deadlocks in the child.
  pid = os.fork()

[2024-11-14T03:47:22.713+0000] {standard_task_runner.py:63} INFO - Started process 3607 to run task
[2024-11-14T03:47:22.694+0000] {standard_task_runner.py:90} INFO - Running: ['***', 'tasks', 'run', 'BuildELT_dbt', 'dbt_run', 'manual__2024-11-14T03:47:18.639970+00:00', '--job-id', '185', '--raw', '--subdir', 'DAGS_FOLDER/build_elt_with_dbt.py', '--cfg-path', '/tmp/tmp5rmxute0']
[2024-11-14T03:47:22.754+0000] {standard_task_runner.py:91} INFO - Job 185: Subtask dbt_run
[2024-11-14T03:47:23.005+0000] {task_command.py:426} INFO - Running <TaskInstance: BuildELT_dbt.dbt_run manual__2024-11-14T03:47:18.639970+00:00 [running]> on host 3627cdc70e56
[2024-11-14T03:47:23.381+0000] {taskinstance.py:2648} INFO - Exporting env vars: AIRFLOW_CTX_DAG_OWNER='***' AIRFLOW_CTX_DAG_ID='BuildELT_dbt' AIRFLOW_CTX_TASK_ID='dbt_run' AIRFLOW_CTX_EXECUTION_DATE='2024-11-14T03:47:18.639970+00:00' AIRFLOW_CTX_TRY_NUMBER='1' AIRFLOW_CTX_DAG_RUN_ID='manual__2024-11-14T03:47:18.639970+00:00'
[2024-11-14T03:47:23.405+0000] {taskinstance.py:430} INFO - ::endgroup::
[2024-11-14T03:47:23.416+0000] {subprocess.py:63} INFO - Tmp dir root location: /tmp
[2024-11-14T03:47:23.418+0000] {subprocess.py:75} INFO - Running command: ['/usr/bin/bash', '-c', '/home/***/.local/bin/dbt run --profiles-dir /opt/***/build_dbt --project-dir /opt/***/build_dbt']
[2024-11-14T03:47:23.466+0000] {subprocess.py:86} INFO - Output:
[2024-11-14T03:47:29.167+0000] {subprocess.py:93} INFO - [0m03:47:29  Running with dbt=1.8.7
[2024-11-14T03:47:33.776+0000] {subprocess.py:93} INFO - [0m03:47:33  Registered adapter: snowflake=1.8.4
[2024-11-14T03:47:34.213+0000] {subprocess.py:93} INFO - [0m03:47:34  [[33mWARNING[0m]: Configuration paths exist in your dbt_project.yml file which do not apply to any resources.
[2024-11-14T03:47:34.215+0000] {subprocess.py:93} INFO - There are 1 unused configuration paths:
[2024-11-14T03:47:34.216+0000] {subprocess.py:93} INFO - - models.build_dbt.example
[2024-11-14T03:47:34.704+0000] {subprocess.py:93} INFO - [0m03:47:34  Found 4 models, 2 sources, 459 macros
[2024-11-14T03:47:34.716+0000] {subprocess.py:93} INFO - [0m03:47:34
[2024-11-14T03:47:38.592+0000] {subprocess.py:93} INFO - [0m03:47:38  Concurrency: 1 threads (target='dev')
[2024-11-14T03:47:38.598+0000] {subprocess.py:93} INFO - [0m03:47:38
[2024-11-14T03:47:38.620+0000] {subprocess.py:93} INFO - [0m03:47:38  1 of 4 START sql table model analytics.moving_average .......................... [RUN]
[2024-11-14T03:47:40.966+0000] {subprocess.py:93} INFO - [0m03:47:40  1 of 4 OK created sql table model analytics.moving_average ..................... [[32mSUCCESS 1[0m in 2.33s]
[2024-11-14T03:47:40.976+0000] {subprocess.py:93} INFO - [0m03:47:40  2 of 4 START sql view model analytics.raw_stock_data ........................... [RUN]
[2024-11-14T03:47:42.701+0000] {subprocess.py:93} INFO - [0m03:47:42  2 of 4 OK created sql view model analytics.raw_stock_data ...................... [[32mSUCCESS 1[0m in 1.72s]
[2024-11-14T03:47:42.709+0000] {subprocess.py:93} INFO - [0m03:47:42  3 of 4 START sql view model analytics.rsi ...................................... [RUN]
[2024-11-14T03:47:44.297+0000] {subprocess.py:93} INFO - [0m03:47:44  3 of 4 ERROR creating sql view model analytics.rsi ............................. [[31mERROR[0m in 1.58s]
[2024-11-14T03:47:44.319+0000] {subprocess.py:93} INFO - [0m03:47:44  4 of 4 SKIP relation analytics.stock_analytics ................................. [[33mSKIP[0m]
[2024-11-14T03:47:44.328+0000] {subprocess.py:93} INFO - [0m03:47:44
[2024-11-14T03:47:44.330+0000] {subprocess.py:93} INFO - [0m03:47:44  Finished running 2 table models, 2 view models in 0 hours 0 minutes and 9.61 seconds (9.61s).
[2024-11-14T03:47:44.439+0000] {subprocess.py:93} INFO - [0m03:47:44
[2024-11-14T03:47:44.441+0000] {subprocess.py:93} INFO - [0m03:47:44  [31mCompleted with 1 error and 0 warnings:[0m
[2024-11-14T03:47:44.442+0000] {subprocess.py:93} INFO - [0m03:47:44
[2024-11-14T03:47:44.444+0000] {subprocess.py:93} INFO - [0m03:47:44    Database Error in model rsi (models/output/rsi.sql)
[2024-11-14T03:47:44.444+0000] {subprocess.py:93} INFO -   001003 (42000): SQL compilation error:
[2024-11-14T03:47:44.446+0000] {subprocess.py:93} INFO -   syntax error line 30 at position 3 unexpected ';'.
[2024-11-14T03:47:44.446+0000] {subprocess.py:93} INFO -   compiled code at target/run/build_dbt/models/output/rsi.sql
[2024-11-14T03:47:44.447+0000] {subprocess.py:93} INFO - [0m03:47:44
[2024-11-14T03:47:44.448+0000] {subprocess.py:93} INFO - [0m03:47:44  Done. PASS=2 WARN=0 ERROR=1 SKIP=1 TOTAL=4
[2024-11-14T03:47:45.572+0000] {subprocess.py:97} INFO - Command exited with return code 1
[2024-11-14T03:47:45.579+0000] {taskinstance.py:441} INFO - ::group::Post task execution logs
[2024-11-14T03:47:45.609+0000] {taskinstance.py:2905} ERROR - Task failed with exception
Traceback (most recent call last):
  File "/home/airflow/.local/lib/python3.12/site-packages/airflow/models/taskinstance.py", line 465, in _execute_task
    result = _execute_callable(context=context, **execute_callable_kwargs)
             ^^^^^^^^^^^^^^^^^^^^^^^^^^^^^^^^^^^^^^^^^^^^^^^^^^^^^^^^^^^^^
  File "/home/airflow/.local/lib/python3.12/site-packages/airflow/models/taskinstance.py", line 432, in _execute_callable
    return execute_callable(context=context, **execute_callable_kwargs)
           ^^^^^^^^^^^^^^^^^^^^^^^^^^^^^^^^^^^^^^^^^^^^^^^^^^^^^^^^^^^^
  File "/home/airflow/.local/lib/python3.12/site-packages/airflow/models/baseoperator.py", line 400, in wrapper
    return func(self, *args, **kwargs)
           ^^^^^^^^^^^^^^^^^^^^^^^^^^^
  File "/home/airflow/.local/lib/python3.12/site-packages/airflow/operators/bash.py", line 243, in execute
    raise AirflowException(
airflow.exceptions.AirflowException: Bash command failed. The command returned a non-zero exit code 1.
[2024-11-14T03:47:45.624+0000] {taskinstance.py:1206} INFO - Marking task as FAILED. dag_id=BuildELT_dbt, task_id=dbt_run, run_id=manual__2024-11-14T03:47:18.639970+00:00, execution_date=20241114T034718, start_date=20241114T034722, end_date=20241114T034745
[2024-11-14T03:47:45.651+0000] {standard_task_runner.py:110} ERROR - Failed to execute job 185 for task dbt_run (Bash command failed. The command returned a non-zero exit code 1.; 3607)
[2024-11-14T03:47:45.711+0000] {local_task_job_runner.py:240} INFO - Task exited with return code 1
[2024-11-14T03:47:45.758+0000] {taskinstance.py:3498} INFO - 0 downstream tasks scheduled from follow-on schedule check
[2024-11-14T03:47:45.763+0000] {local_task_job_runner.py:222} INFO - ::endgroup::
