[2024-11-14T03:40:35.226+0000] {local_task_job_runner.py:120} INFO - ::group::Pre task execution logs
[2024-11-14T03:40:35.676+0000] {taskinstance.py:2076} INFO - Dependencies all met for dep_context=non-requeueable deps ti=<TaskInstance: BuildELT_dbt.dbt_run manual__2024-11-14T03:40:20.329363+00:00 [queued]>
[2024-11-14T03:40:35.730+0000] {taskinstance.py:2076} INFO - Dependencies all met for dep_context=requeueable deps ti=<TaskInstance: BuildELT_dbt.dbt_run manual__2024-11-14T03:40:20.329363+00:00 [queued]>
[2024-11-14T03:40:35.732+0000] {taskinstance.py:2306} INFO - Starting attempt 1 of 1
[2024-11-14T03:40:35.802+0000] {taskinstance.py:2330} INFO - Executing <Task(BashOperator): dbt_run> on 2024-11-14 03:40:20.329363+00:00
[2024-11-14T03:40:35.853+0000] {warnings.py:110} WARNING - /home/***/.local/lib/python3.12/site-packages/***/task/task_runner/standard_task_runner.py:61: DeprecationWarning: This process (pid=3450) is multi-threaded, use of fork() may lead to deadlocks in the child.
  pid = os.fork()

[2024-11-14T03:40:35.869+0000] {standard_task_runner.py:63} INFO - Started process 3465 to run task
[2024-11-14T03:40:35.977+0000] {standard_task_runner.py:90} INFO - Running: ['***', 'tasks', 'run', 'BuildELT_dbt', 'dbt_run', 'manual__2024-11-14T03:40:20.329363+00:00', '--job-id', '180', '--raw', '--subdir', 'DAGS_FOLDER/build_elt_with_dbt.py', '--cfg-path', '/tmp/tmpicl3co5l']
[2024-11-14T03:40:36.066+0000] {standard_task_runner.py:91} INFO - Job 180: Subtask dbt_run
[2024-11-14T03:40:36.939+0000] {task_command.py:426} INFO - Running <TaskInstance: BuildELT_dbt.dbt_run manual__2024-11-14T03:40:20.329363+00:00 [running]> on host 3627cdc70e56
[2024-11-14T03:40:37.690+0000] {taskinstance.py:2648} INFO - Exporting env vars: AIRFLOW_CTX_DAG_OWNER='***' AIRFLOW_CTX_DAG_ID='BuildELT_dbt' AIRFLOW_CTX_TASK_ID='dbt_run' AIRFLOW_CTX_EXECUTION_DATE='2024-11-14T03:40:20.329363+00:00' AIRFLOW_CTX_TRY_NUMBER='1' AIRFLOW_CTX_DAG_RUN_ID='manual__2024-11-14T03:40:20.329363+00:00'
[2024-11-14T03:40:37.733+0000] {taskinstance.py:430} INFO - ::endgroup::
[2024-11-14T03:40:37.751+0000] {subprocess.py:63} INFO - Tmp dir root location: /tmp
[2024-11-14T03:40:37.758+0000] {subprocess.py:75} INFO - Running command: ['/usr/bin/bash', '-c', '/home/***/.local/bin/dbt run --profiles-dir /opt/***/build_dbt --project-dir /opt/***/build_dbt']
[2024-11-14T03:40:37.806+0000] {subprocess.py:86} INFO - Output:
[2024-11-14T03:40:46.705+0000] {subprocess.py:93} INFO - [0m03:40:46  Running with dbt=1.8.7
[2024-11-14T03:40:48.421+0000] {subprocess.py:93} INFO - [0m03:40:48  Registered adapter: snowflake=1.8.4
[2024-11-14T03:40:49.487+0000] {subprocess.py:93} INFO - [0m03:40:49  Encountered an error:
[2024-11-14T03:40:49.497+0000] {subprocess.py:93} INFO - Compilation Error in snapshot stock_price_snapshot (snapshots/stock_price_snapshot.sql)
[2024-11-14T03:40:49.500+0000] {subprocess.py:93} INFO -   invalid syntax for function call expression
[2024-11-14T03:40:49.503+0000] {subprocess.py:93} INFO -     line 3
[2024-11-14T03:40:49.507+0000] {subprocess.py:93} INFO -       config(
[2024-11-14T03:40:51.119+0000] {subprocess.py:97} INFO - Command exited with return code 2
[2024-11-14T03:40:51.130+0000] {taskinstance.py:441} INFO - ::group::Post task execution logs
[2024-11-14T03:40:51.178+0000] {taskinstance.py:2905} ERROR - Task failed with exception
Traceback (most recent call last):
  File "/home/airflow/.local/lib/python3.12/site-packages/airflow/models/taskinstance.py", line 465, in _execute_task
    result = _execute_callable(context=context, **execute_callable_kwargs)
             ^^^^^^^^^^^^^^^^^^^^^^^^^^^^^^^^^^^^^^^^^^^^^^^^^^^^^^^^^^^^^
  File "/home/airflow/.local/lib/python3.12/site-packages/airflow/models/taskinstance.py", line 432, in _execute_callable
    return execute_callable(context=context, **execute_callable_kwargs)
           ^^^^^^^^^^^^^^^^^^^^^^^^^^^^^^^^^^^^^^^^^^^^^^^^^^^^^^^^^^^^
  File "/home/airflow/.local/lib/python3.12/site-packages/airflow/models/baseoperator.py", line 400, in wrapper
    return func(self, *args, **kwargs)
           ^^^^^^^^^^^^^^^^^^^^^^^^^^^
  File "/home/airflow/.local/lib/python3.12/site-packages/airflow/operators/bash.py", line 243, in execute
    raise AirflowException(
airflow.exceptions.AirflowException: Bash command failed. The command returned a non-zero exit code 2.
[2024-11-14T03:40:51.200+0000] {taskinstance.py:1206} INFO - Marking task as FAILED. dag_id=BuildELT_dbt, task_id=dbt_run, run_id=manual__2024-11-14T03:40:20.329363+00:00, execution_date=20241114T034020, start_date=20241114T034035, end_date=20241114T034051
[2024-11-14T03:40:51.232+0000] {standard_task_runner.py:110} ERROR - Failed to execute job 180 for task dbt_run (Bash command failed. The command returned a non-zero exit code 2.; 3465)
[2024-11-14T03:40:51.307+0000] {local_task_job_runner.py:240} INFO - Task exited with return code 1
[2024-11-14T03:40:51.341+0000] {taskinstance.py:3498} INFO - 0 downstream tasks scheduled from follow-on schedule check
[2024-11-14T03:40:51.346+0000] {local_task_job_runner.py:222} INFO - ::endgroup::
