[2024-11-14T03:46:27.974+0000] {local_task_job_runner.py:120} INFO - ::group::Pre task execution logs
[2024-11-14T03:46:28.000+0000] {taskinstance.py:2076} INFO - Dependencies all met for dep_context=non-requeueable deps ti=<TaskInstance: BuildELT_dbt.dbt_run manual__2024-11-14T03:46:25.130407+00:00 [queued]>
[2024-11-14T03:46:28.011+0000] {taskinstance.py:2076} INFO - Dependencies all met for dep_context=requeueable deps ti=<TaskInstance: BuildELT_dbt.dbt_run manual__2024-11-14T03:46:25.130407+00:00 [queued]>
[2024-11-14T03:46:28.014+0000] {taskinstance.py:2306} INFO - Starting attempt 1 of 1
[2024-11-14T03:46:28.029+0000] {taskinstance.py:2330} INFO - Executing <Task(BashOperator): dbt_run> on 2024-11-14 03:46:25.130407+00:00
[2024-11-14T03:46:28.042+0000] {warnings.py:110} WARNING - /home/***/.local/lib/python3.12/site-packages/***/task/task_runner/standard_task_runner.py:61: DeprecationWarning: This process (pid=3571) is multi-threaded, use of fork() may lead to deadlocks in the child.
  pid = os.fork()

[2024-11-14T03:46:28.045+0000] {standard_task_runner.py:63} INFO - Started process 3573 to run task
[2024-11-14T03:46:28.045+0000] {standard_task_runner.py:90} INFO - Running: ['***', 'tasks', 'run', 'BuildELT_dbt', 'dbt_run', 'manual__2024-11-14T03:46:25.130407+00:00', '--job-id', '184', '--raw', '--subdir', 'DAGS_FOLDER/build_elt_with_dbt.py', '--cfg-path', '/tmp/tmpm6ovslck']
[2024-11-14T03:46:28.049+0000] {standard_task_runner.py:91} INFO - Job 184: Subtask dbt_run
[2024-11-14T03:46:28.085+0000] {task_command.py:426} INFO - Running <TaskInstance: BuildELT_dbt.dbt_run manual__2024-11-14T03:46:25.130407+00:00 [running]> on host 3627cdc70e56
[2024-11-14T03:46:28.148+0000] {taskinstance.py:2648} INFO - Exporting env vars: AIRFLOW_CTX_DAG_OWNER='***' AIRFLOW_CTX_DAG_ID='BuildELT_dbt' AIRFLOW_CTX_TASK_ID='dbt_run' AIRFLOW_CTX_EXECUTION_DATE='2024-11-14T03:46:25.130407+00:00' AIRFLOW_CTX_TRY_NUMBER='1' AIRFLOW_CTX_DAG_RUN_ID='manual__2024-11-14T03:46:25.130407+00:00'
[2024-11-14T03:46:28.151+0000] {taskinstance.py:430} INFO - ::endgroup::
[2024-11-14T03:46:28.153+0000] {subprocess.py:63} INFO - Tmp dir root location: /tmp
[2024-11-14T03:46:28.154+0000] {subprocess.py:75} INFO - Running command: ['/usr/bin/bash', '-c', '/home/***/.local/bin/dbt run --profiles-dir /opt/***/build_dbt --project-dir /opt/***/build_dbt']
[2024-11-14T03:46:28.166+0000] {subprocess.py:86} INFO - Output:
[2024-11-14T03:46:29.757+0000] {subprocess.py:93} INFO - [0m03:46:29  Running with dbt=1.8.7
[2024-11-14T03:46:31.032+0000] {subprocess.py:93} INFO - [0m03:46:31  Registered adapter: snowflake=1.8.4
[2024-11-14T03:46:31.458+0000] {subprocess.py:93} INFO - [0m03:46:31  [[33mWARNING[0m]: Configuration paths exist in your dbt_project.yml file which do not apply to any resources.
[2024-11-14T03:46:31.460+0000] {subprocess.py:93} INFO - There are 1 unused configuration paths:
[2024-11-14T03:46:31.460+0000] {subprocess.py:93} INFO - - models.build_dbt.example
[2024-11-14T03:46:31.651+0000] {subprocess.py:93} INFO - [0m03:46:31  Found 4 models, 1 snapshot, 2 sources, 459 macros
[2024-11-14T03:46:31.657+0000] {subprocess.py:93} INFO - [0m03:46:31
[2024-11-14T03:46:37.154+0000] {subprocess.py:93} INFO - [0m03:46:37  Concurrency: 1 threads (target='dev')
[2024-11-14T03:46:37.167+0000] {subprocess.py:93} INFO - [0m03:46:37
[2024-11-14T03:46:37.196+0000] {subprocess.py:93} INFO - [0m03:46:37  1 of 4 START sql table model analytics.moving_average .......................... [RUN]
[2024-11-14T03:46:39.813+0000] {subprocess.py:93} INFO - [0m03:46:39  1 of 4 OK created sql table model analytics.moving_average ..................... [[32mSUCCESS 1[0m in 2.60s]
[2024-11-14T03:46:39.829+0000] {subprocess.py:93} INFO - [0m03:46:39  2 of 4 START sql view model analytics.raw_stock_data ........................... [RUN]
[2024-11-14T03:46:41.508+0000] {subprocess.py:93} INFO - [0m03:46:41  2 of 4 OK created sql view model analytics.raw_stock_data ...................... [[32mSUCCESS 1[0m in 1.67s]
[2024-11-14T03:46:41.518+0000] {subprocess.py:93} INFO - [0m03:46:41  3 of 4 START sql view model analytics.rsi ...................................... [RUN]
[2024-11-14T03:46:43.064+0000] {subprocess.py:93} INFO - [0m03:46:43  3 of 4 ERROR creating sql view model analytics.rsi ............................. [[31mERROR[0m in 1.54s]
[2024-11-14T03:46:43.080+0000] {subprocess.py:93} INFO - [0m03:46:43  4 of 4 SKIP relation analytics.stock_analytics ................................. [[33mSKIP[0m]
[2024-11-14T03:46:43.094+0000] {subprocess.py:93} INFO - [0m03:46:43
[2024-11-14T03:46:43.096+0000] {subprocess.py:93} INFO - [0m03:46:43  Finished running 2 table models, 2 view models in 0 hours 0 minutes and 11.43 seconds (11.43s).
[2024-11-14T03:46:43.189+0000] {subprocess.py:93} INFO - [0m03:46:43
[2024-11-14T03:46:43.191+0000] {subprocess.py:93} INFO - [0m03:46:43  [31mCompleted with 1 error and 0 warnings:[0m
[2024-11-14T03:46:43.193+0000] {subprocess.py:93} INFO - [0m03:46:43
[2024-11-14T03:46:43.195+0000] {subprocess.py:93} INFO - [0m03:46:43    Database Error in model rsi (models/output/rsi.sql)
[2024-11-14T03:46:43.196+0000] {subprocess.py:93} INFO -   001003 (42000): SQL compilation error:
[2024-11-14T03:46:43.196+0000] {subprocess.py:93} INFO -   syntax error line 30 at position 3 unexpected ';'.
[2024-11-14T03:46:43.197+0000] {subprocess.py:93} INFO -   compiled code at target/run/build_dbt/models/output/rsi.sql
[2024-11-14T03:46:43.198+0000] {subprocess.py:93} INFO - [0m03:46:43
[2024-11-14T03:46:43.199+0000] {subprocess.py:93} INFO - [0m03:46:43  Done. PASS=2 WARN=0 ERROR=1 SKIP=1 TOTAL=4
[2024-11-14T03:46:44.130+0000] {subprocess.py:97} INFO - Command exited with return code 1
[2024-11-14T03:46:44.135+0000] {taskinstance.py:441} INFO - ::group::Post task execution logs
[2024-11-14T03:46:44.173+0000] {taskinstance.py:2905} ERROR - Task failed with exception
Traceback (most recent call last):
  File "/home/airflow/.local/lib/python3.12/site-packages/airflow/models/taskinstance.py", line 465, in _execute_task
    result = _execute_callable(context=context, **execute_callable_kwargs)
             ^^^^^^^^^^^^^^^^^^^^^^^^^^^^^^^^^^^^^^^^^^^^^^^^^^^^^^^^^^^^^
  File "/home/airflow/.local/lib/python3.12/site-packages/airflow/models/taskinstance.py", line 432, in _execute_callable
    return execute_callable(context=context, **execute_callable_kwargs)
           ^^^^^^^^^^^^^^^^^^^^^^^^^^^^^^^^^^^^^^^^^^^^^^^^^^^^^^^^^^^^
  File "/home/airflow/.local/lib/python3.12/site-packages/airflow/models/baseoperator.py", line 400, in wrapper
    return func(self, *args, **kwargs)
           ^^^^^^^^^^^^^^^^^^^^^^^^^^^
  File "/home/airflow/.local/lib/python3.12/site-packages/airflow/operators/bash.py", line 243, in execute
    raise AirflowException(
airflow.exceptions.AirflowException: Bash command failed. The command returned a non-zero exit code 1.
[2024-11-14T03:46:44.190+0000] {taskinstance.py:1206} INFO - Marking task as FAILED. dag_id=BuildELT_dbt, task_id=dbt_run, run_id=manual__2024-11-14T03:46:25.130407+00:00, execution_date=20241114T034625, start_date=20241114T034628, end_date=20241114T034644
[2024-11-14T03:46:44.218+0000] {standard_task_runner.py:110} ERROR - Failed to execute job 184 for task dbt_run (Bash command failed. The command returned a non-zero exit code 1.; 3573)
[2024-11-14T03:46:44.289+0000] {local_task_job_runner.py:240} INFO - Task exited with return code 1
[2024-11-14T03:46:44.334+0000] {taskinstance.py:3498} INFO - 0 downstream tasks scheduled from follow-on schedule check
[2024-11-14T03:46:44.339+0000] {local_task_job_runner.py:222} INFO - ::endgroup::
