[2024-11-14T04:17:57.552+0000] {local_task_job_runner.py:120} INFO - ::group::Pre task execution logs
[2024-11-14T04:17:57.618+0000] {taskinstance.py:2076} INFO - Dependencies all met for dep_context=non-requeueable deps ti=<TaskInstance: BuildELT_dbt.dbt_run manual__2024-11-14T04:17:51.887853+00:00 [queued]>
[2024-11-14T04:17:57.640+0000] {taskinstance.py:2076} INFO - Dependencies all met for dep_context=requeueable deps ti=<TaskInstance: BuildELT_dbt.dbt_run manual__2024-11-14T04:17:51.887853+00:00 [queued]>
[2024-11-14T04:17:57.645+0000] {taskinstance.py:2306} INFO - Starting attempt 1 of 1
[2024-11-14T04:17:57.670+0000] {taskinstance.py:2330} INFO - Executing <Task(BashOperator): dbt_run> on 2024-11-14 04:17:51.887853+00:00
[2024-11-14T04:17:57.730+0000] {warnings.py:110} WARNING - /home/***/.local/lib/python3.12/site-packages/***/task/task_runner/standard_task_runner.py:61: DeprecationWarning: This process (pid=4206) is multi-threaded, use of fork() may lead to deadlocks in the child.
  pid = os.fork()

[2024-11-14T04:17:57.744+0000] {standard_task_runner.py:63} INFO - Started process 4208 to run task
[2024-11-14T04:17:57.746+0000] {standard_task_runner.py:90} INFO - Running: ['***', 'tasks', 'run', 'BuildELT_dbt', 'dbt_run', 'manual__2024-11-14T04:17:51.887853+00:00', '--job-id', '214', '--raw', '--subdir', 'DAGS_FOLDER/build_elt_with_dbt.py', '--cfg-path', '/tmp/tmpvrz62nn5']
[2024-11-14T04:17:57.768+0000] {standard_task_runner.py:91} INFO - Job 214: Subtask dbt_run
[2024-11-14T04:17:57.919+0000] {task_command.py:426} INFO - Running <TaskInstance: BuildELT_dbt.dbt_run manual__2024-11-14T04:17:51.887853+00:00 [running]> on host 3627cdc70e56
[2024-11-14T04:17:58.087+0000] {taskinstance.py:2648} INFO - Exporting env vars: AIRFLOW_CTX_DAG_OWNER='***' AIRFLOW_CTX_DAG_ID='BuildELT_dbt' AIRFLOW_CTX_TASK_ID='dbt_run' AIRFLOW_CTX_EXECUTION_DATE='2024-11-14T04:17:51.887853+00:00' AIRFLOW_CTX_TRY_NUMBER='1' AIRFLOW_CTX_DAG_RUN_ID='manual__2024-11-14T04:17:51.887853+00:00'
[2024-11-14T04:17:58.110+0000] {taskinstance.py:430} INFO - ::endgroup::
[2024-11-14T04:17:58.118+0000] {subprocess.py:63} INFO - Tmp dir root location: /tmp
[2024-11-14T04:17:58.125+0000] {subprocess.py:75} INFO - Running command: ['/usr/bin/bash', '-c', '/home/***/.local/bin/dbt run --profiles-dir /opt/***/build_dbt --project-dir /opt/***/build_dbt']
[2024-11-14T04:17:58.181+0000] {subprocess.py:86} INFO - Output:
[2024-11-14T04:18:05.597+0000] {subprocess.py:93} INFO - [0m04:18:05  Running with dbt=1.8.7
[2024-11-14T04:18:08.198+0000] {subprocess.py:93} INFO - [0m04:18:08  Registered adapter: snowflake=1.8.4
[2024-11-14T04:18:09.551+0000] {subprocess.py:93} INFO - [0m04:18:09  [[33mWARNING[0m]: Configuration paths exist in your dbt_project.yml file which do not apply to any resources.
[2024-11-14T04:18:09.566+0000] {subprocess.py:93} INFO - There are 1 unused configuration paths:
[2024-11-14T04:18:09.569+0000] {subprocess.py:93} INFO - - models.build_dbt.example
[2024-11-14T04:18:09.830+0000] {subprocess.py:93} INFO - [0m04:18:09  Found 4 models, 1 snapshot, 2 sources, 459 macros
[2024-11-14T04:18:09.839+0000] {subprocess.py:93} INFO - [0m04:18:09
[2024-11-14T04:18:15.228+0000] {subprocess.py:93} INFO - [0m04:18:15  Concurrency: 1 threads (target='dev')
[2024-11-14T04:18:15.241+0000] {subprocess.py:93} INFO - [0m04:18:15
[2024-11-14T04:18:15.277+0000] {subprocess.py:93} INFO - [0m04:18:15  1 of 4 START sql table model analytics.moving_average .......................... [RUN]
[2024-11-14T04:18:17.454+0000] {subprocess.py:93} INFO - [0m04:18:17  1 of 4 OK created sql table model analytics.moving_average ..................... [[32mSUCCESS 1[0m in 2.14s]
[2024-11-14T04:18:17.475+0000] {subprocess.py:93} INFO - [0m04:18:17  2 of 4 START sql view model analytics.raw_stock_data ........................... [RUN]
[2024-11-14T04:18:19.154+0000] {subprocess.py:93} INFO - [0m04:18:19  2 of 4 OK created sql view model analytics.raw_stock_data ...................... [[32mSUCCESS 1[0m in 1.67s]
[2024-11-14T04:18:19.164+0000] {subprocess.py:93} INFO - [0m04:18:19  3 of 4 START sql view model analytics.rsi ...................................... [RUN]
[2024-11-14T04:18:20.750+0000] {subprocess.py:93} INFO - [0m04:18:20  3 of 4 ERROR creating sql view model analytics.rsi ............................. [[31mERROR[0m in 1.58s]
[2024-11-14T04:18:20.778+0000] {subprocess.py:93} INFO - [0m04:18:20  4 of 4 SKIP relation analytics.stock_analytics ................................. [[33mSKIP[0m]
[2024-11-14T04:18:20.791+0000] {subprocess.py:93} INFO - [0m04:18:20
[2024-11-14T04:18:20.793+0000] {subprocess.py:93} INFO - [0m04:18:20  Finished running 2 table models, 2 view models in 0 hours 0 minutes and 10.95 seconds (10.95s).
[2024-11-14T04:18:21.086+0000] {subprocess.py:93} INFO - [0m04:18:21
[2024-11-14T04:18:21.091+0000] {subprocess.py:93} INFO - [0m04:18:21  [31mCompleted with 1 error and 0 warnings:[0m
[2024-11-14T04:18:21.098+0000] {subprocess.py:93} INFO - [0m04:18:21
[2024-11-14T04:18:21.104+0000] {subprocess.py:93} INFO - [0m04:18:21    Database Error in model rsi (models/output/rsi.sql)
[2024-11-14T04:18:21.108+0000] {subprocess.py:93} INFO -   001003 (42000): SQL compilation error:
[2024-11-14T04:18:21.115+0000] {subprocess.py:93} INFO -   syntax error line 10 at position 8 unexpected ';'.
[2024-11-14T04:18:21.126+0000] {subprocess.py:93} INFO -   compiled code at target/run/build_dbt/models/output/rsi.sql
[2024-11-14T04:18:21.131+0000] {subprocess.py:93} INFO - [0m04:18:21
[2024-11-14T04:18:21.136+0000] {subprocess.py:93} INFO - [0m04:18:21  Done. PASS=2 WARN=0 ERROR=1 SKIP=1 TOTAL=4
[2024-11-14T04:18:22.400+0000] {subprocess.py:97} INFO - Command exited with return code 1
[2024-11-14T04:18:22.412+0000] {taskinstance.py:441} INFO - ::group::Post task execution logs
[2024-11-14T04:18:22.452+0000] {taskinstance.py:2905} ERROR - Task failed with exception
Traceback (most recent call last):
  File "/home/airflow/.local/lib/python3.12/site-packages/airflow/models/taskinstance.py", line 465, in _execute_task
    result = _execute_callable(context=context, **execute_callable_kwargs)
             ^^^^^^^^^^^^^^^^^^^^^^^^^^^^^^^^^^^^^^^^^^^^^^^^^^^^^^^^^^^^^
  File "/home/airflow/.local/lib/python3.12/site-packages/airflow/models/taskinstance.py", line 432, in _execute_callable
    return execute_callable(context=context, **execute_callable_kwargs)
           ^^^^^^^^^^^^^^^^^^^^^^^^^^^^^^^^^^^^^^^^^^^^^^^^^^^^^^^^^^^^
  File "/home/airflow/.local/lib/python3.12/site-packages/airflow/models/baseoperator.py", line 400, in wrapper
    return func(self, *args, **kwargs)
           ^^^^^^^^^^^^^^^^^^^^^^^^^^^
  File "/home/airflow/.local/lib/python3.12/site-packages/airflow/operators/bash.py", line 243, in execute
    raise AirflowException(
airflow.exceptions.AirflowException: Bash command failed. The command returned a non-zero exit code 1.
[2024-11-14T04:18:22.468+0000] {taskinstance.py:1206} INFO - Marking task as FAILED. dag_id=BuildELT_dbt, task_id=dbt_run, run_id=manual__2024-11-14T04:17:51.887853+00:00, execution_date=20241114T041751, start_date=20241114T041757, end_date=20241114T041822
[2024-11-14T04:18:22.507+0000] {standard_task_runner.py:110} ERROR - Failed to execute job 214 for task dbt_run (Bash command failed. The command returned a non-zero exit code 1.; 4208)
[2024-11-14T04:18:22.598+0000] {local_task_job_runner.py:240} INFO - Task exited with return code 1
[2024-11-14T04:18:22.685+0000] {taskinstance.py:3498} INFO - 0 downstream tasks scheduled from follow-on schedule check
[2024-11-14T04:18:22.704+0000] {local_task_job_runner.py:222} INFO - ::endgroup::
